{
  "comments": [
    {
      "key": {
        "uuid": "a5513673_a396b220",
        "filename": "appengine/components/components/auth/replication.py",
        "patchSetId": 2
      },
      "lineNbr": 429,
      "author": {
        "id": 1001907
      },
      "writtenOn": "2020-03-12T21:29:17Z",
      "side": 0,
      "message": "This seems like it should be a separate bug fix CL? When could this mismatch actually occur?",
      "range": {
        "startLine": 429,
        "startChar": 6,
        "endLine": 429,
        "endChar": 11
      },
      "revId": "ebe8867061223492cdf5910ec642076ee519ec5b",
      "serverId": "3ce6091f-6c88-37e8-8c75-72f92ae8dfba",
      "unresolved": true
    }
  ]
}